Workbook

Sheet DASHBOARD
A1: KDV BEYANNAME ROBOTU - DASHBOARD / MERKEZLER HARİÇ
A2: Toplam 391 / Hesaplanan+İlave | B2: =KDV_BEYAN_ICMAL!O10
A3: Toplam 191 / İndirilecek+İade | B3: =KDV_BEYAN_ICMAL!P10 | D3: Şube | E3: Net KDV | F3: Sonuç | G3: Kritik Fark | H3: 600/391 Fark | I3: 610/191 Fark | J3: Beyanname Notu | K3: Hatalı KDV Nedeni | L3: Kontrol Edilecek Alan
A4: Net KDV | B4: =KDV_BEYAN_ICMAL!Q10
A5: Genel Sonuç | B5: =KDV_BEYAN_ICMAL!R10
A6: Kritik/Küçük Fark Sayısı | B6: =SUM(KDV_HESAP_TABANI!AQ2:AQ7)
A7: Tevkifatlı İndirilecek KDV | B7: =SUM(KDV_HESAP_TABANI!AI2:AI7)
A8: Dashboard Hata Nedeni | B8: =IF(SUM(KDV_HESAP_TABANI!AQ2:AQ7)=0,"Kritik hata yok",IF(KDV_HESAP_TABANI!AQ2>0,KDV_HESAP_TABANI!AR2,IF(KDV_HESAP_TABANI!AQ3>0,KDV_HESAP_TABANI!AR3,IF(KDV_HESAP_TABANI!AQ4>0,KDV_HESAP_TABANI!AR4,IF(KDV_HESAP_TABANI!AQ5>0,KDV_HESAP_TABANI!AR5,IF(KDV_HESAP_TABANI!AQ6>0,KDV_HESAP_TABANI!AR6,KDV_HESAP_TABANI!AR7)))))) | D8: =KDV_HESAP_TABANI!A2 | E8: =KDV_HESAP_TABANI!AO2 | F8: =KDV_HESAP_TABANI!AP2 | G8: =KDV_HESAP_TABANI!AQ2 | H8: =KDV_HESAP_TABANI!E2+KDV_HESAP_TABANI!J2 | I8: =KDV_HESAP_TABANI!O2+KDV_HESAP_TABANI!T2 | J8: =KDV_BEYAN_ICMAL!S4 | K8: =KDV_HESAP_TABANI!AR2 | L8: =KDV_HESAP_TABANI!AS2
D9: =KDV_HESAP_TABANI!A3 | E9: =KDV_HESAP_TABANI!AO3 | F9: =KDV_HESAP_TABANI!AP3 | G9: =KDV_HESAP_TABANI!AQ3 | H9: =KDV_HESAP_TABANI!E3+KDV_HESAP_TABANI!J3 | I9: =KDV_HESAP_TABANI!O3+KDV_HESAP_TABANI!T3 | J9: =KDV_BEYAN_ICMAL!S5 | K9: =KDV_HESAP_TABANI!AR3 | L9: =KDV_HESAP_TABANI!AS3
D10: =KDV_HESAP_TABANI!A4 | E10: =KDV_HESAP_TABANI!AO4 | F10: =KDV_HESAP_TABANI!AP4 | G10: =KDV_HESAP_TABANI!AQ4 | H10: =KDV_HESAP_TABANI!E4+KDV_HESAP_TABANI!J4 | I10: =KDV_HESAP_TABANI!O4+KDV_HESAP_TABANI!T4 | J10: =KDV_BEYAN_ICMAL!S6 | K10: =KDV_HESAP_TABANI!AR4 | L10: =KDV_HESAP_TABANI!AS4
D11: =KDV_HESAP_TABANI!A5 | E11: =KDV_HESAP_TABANI!AO5 | F11: =KDV_HESAP_TABANI!AP5 | G11: =KDV_HESAP_TABANI!AQ5 | H11: =KDV_HESAP_TABANI!E5+KDV_HESAP_TABANI!J5 | I11: =KDV_HESAP_TABANI!O5+KDV_HESAP_TABANI!T5 | J11: =KDV_BEYAN_ICMAL!S7 | K11: =KDV_HESAP_TABANI!AR5 | L11: =KDV_HESAP_TABANI!AS5
D12: =KDV_HESAP_TABANI!A6 | E12: =KDV_HESAP_TABANI!AO6 | F12: =KDV_HESAP_TABANI!AP6 | G12: =KDV_HESAP_TABANI!AQ6 | H12: =KDV_HESAP_TABANI!E6+KDV_HESAP_TABANI!J6 | I12: =KDV_HESAP_TABANI!O6+KDV_HESAP_TABANI!T6 | J12: =KDV_BEYAN_ICMAL!S8 | K12: =KDV_HESAP_TABANI!AR6 | L12: =KDV_HESAP_TABANI!AS6
D13: =KDV_HESAP_TABANI!A7 | E13: =KDV_HESAP_TABANI!AO7 | F13: =KDV_HESAP_TABANI!AP7 | G13: =KDV_HESAP_TABANI!AQ7 | H13: =KDV_HESAP_TABANI!E7+KDV_HESAP_TABANI!J7 | I13: =KDV_HESAP_TABANI!O7+KDV_HESAP_TABANI!T7 | J13: =KDV_BEYAN_ICMAL!S9 | K13: =KDV_HESAP_TABANI!AR7 | L13: =KDV_HESAP_TABANI!AS7

Sheet RAW_HESAP_KARTLARI
A1: Hesap Kodu | B1: Hesap Adı | C1: Kart Dvz | D1: Şube | E1: Borç | F1: Alacak | G1: Bakiye | H1: B/A | I1: Dvz Borç | J1: Dvz Alacak | K1: Dvz Bakiye | L1: Dvz B/A
A2: 1 | B2: DÖNEN VARLIKLAR | C2: TRY | E2: 8.4487762e+09 | F2: 7.8473093e+09 | G2: 6.0146692e+08 | I2: 2.4357832e+09 | J2: 2.2934077e+09 | K2: 1.423755e+08
A3: 10 | B3: HAZIR DEĞERLER | C3: TRY | E3: 6.518574e+09 | F3: 6.7008291e+09 | G3: -1.8225514e+08 | I3: 1.1308049e+09 | J3: 1.2927585e+09 | K3: -1.6195363e+08
A4: 100 | B4: KASA | C4: TRY | E4: 13059627 | F4: 11754551 | G4: 1305076.6 | I4: 1027591.9 | J4: 561595.18 | K4: 465996.71
A5: 100.01 | B5: TL KASASI | C5: TRY | E5: 13059627 | F5: 11754551 | G5: 1305076.6 | I5: 1027591.9 | J5: 561595.18 | K5: 465996.71
A6: 100.01.01 | B6: TL KASASI | C6: TRY | E6: 785662.53 | F6: 340118.45 | G6: 445544.08 | I6: 785662.53 | J6: 340118.45 | K6: 445544.08
A7: 100.01.01.0001 | B7: TL Ana Kasa | C7: TRY | D7: ROYAL ADAM EVE | E7: 0 | F7: 124270 | G7: -124270 | H7: Alacak | I7: 0 | J7: 124270 | K7: -124270 | L7: Alacak
A8: 100.01.01.0001 | B8: TL Ana Kasa | C8: TRY | D8: ROYAL ALHAMBRA | E8: 0 | F8: 855.6 | G8: -855.6 | H8: Alacak | I8: 0 | J8: 855.6 | K8: -855.6 | L8: Alacak
A9: 100.01.01.0001 | B9: TL Ana Kasa | C9: TRY | D9: ROYAL DRAGON | E9: 0 | F9: 10806.26 | G9: -10806.26 | H9: Alacak | I9: 0 | J9: 10806.26 | K9: -10806.26 | L9: Alacak
A10: 100.01.01.0001 | B10: TL Ana Kasa | C10: TRY | D10: ROYAL HOLIDAY | E10: 0 | F10: 110940 | G10: -110940 | H10: Alacak | I10: 0 | J10: 110940 | K10: -110940 | L10: Alacak
A11: 100.01.01.0001 | B11: TL Ana Kasa | C11: TRY | D11: ROYAL SEGINUS | E11: 4835.23 | F11: 92007.15 | G11: -87171.92 | H11: Alacak | I11: 4835.23 | J11: 92007.15 | K11: -87171.92 | L11: Alacak
A12: 100.01.01.0001 | B12: TL Ana Kasa | C12: TRY | D12: SERTAŞ MERKEZ | E12: 0 | F12: 1239.44 | G12: -1239.44 | H12: Alacak | I12: 0 | J12: 1239.44 | K12: -1239.44 | L12: Alacak
A13: 100.01.01.0002 | B13: Önbüro TL Kasası | C13: TRY | D13: ROYAL ADAM EVE | E13: 439734.61 | F13: 0 | G13: 439734.61 | H13: Borç | I13: 439734.61 | J13: 0 | K13: 439734.61 | L13: Borç
A14: 100.01.01.0002 | B14: Önbüro TL Kasası | C14: TRY | D14: ROYAL ALHAMBRA | E14: 1593.67 | F14: 0 | G14: 1593.67 | H14: Borç | I14: 1593.67 | J14: 0 | K14: 1593.67 | L14: Borç
A15: 100.01.01.0002 | B15: Önbüro TL Kasası | C15: TRY | D15: ROYAL DRAGON | E15: 1272.34 | F15: 0 | G15: 1272.34 | H15: Borç | I15: 1272.34 | J15: 0 | K15: 1272.34 | L15: Borç
A16: 100.01.01.0002 | B16: Önbüro TL Kasası | C16: TRY | D16: ROYAL HOLIDAY | E16: 134737.86 | F16: 0 | G16: 134737.86 | H16: Borç | I16: 134737.86 | J16: 0 | K16: 134737.86 | L16: Borç
A17: 100.01.01.0002 | B17: Önbüro TL Kasası | C17: TRY | D17: ROYAL SEGINUS | E17: 203488.82 | F17: 0 | G17: 203488.82 | H17: Borç | I17: 203488.82 | J17: 0 | K17: 203488.82 | L17: Borç
A18: 100.01.02 | B18: DÖVİZ KASASI | C18: TRY | E18: 12273965 | F18: 11414432 | G18: 859532.48 | I18: 241929.36 | J18: 221476.73 | K18: 20452.63
A19: 100.01.02.0001 | B19: Usd Kasası | C19: USD | D19: ROYAL ADAM EVE | E19: 448437.79 | F19: 1249035.7 | G19: -800597.95 | H19: Alacak | I19: 9700 | J19: 27170 | K19: -17470 | L19: Alacak
A20: 100.01.02.0001 | B20: Usd Kasası | C20: USD | D20: ROYAL HOLIDAY | E20: 0 | F20: 320994.15 | G20: -320994.15 | H20: Alacak | I20: 0 | J20: 6968 | K20: -6968 | L20: Alacak
A21: 100.01.02.0001 | B21: Usd Kasası | C21: USD | D21: ROYAL SEGINUS | E21: 0 | F21: 983568.99 | G21: -983568.99 | H21: Alacak | I21: 0 | J21: 21371 | K21: -21371 | L21: Alacak
A22: 100.01.02.0002 | B22: Euro Kasası | C22: EUR | D22: GİTAŞ MERKEZ | E22: 72619.27 | F22: 1218641.5 | G22: -1146022.2 | H22: Alacak | I22: 1360 | J22: 22914.9 | K22: -21554.9 | L22: Alacak
A23: 100.01.02.0002 | B23: Euro Kasası | C23: EUR | D23: ROYAL ADAM EVE | E23: 82567.84 | F23: 2315611.4 | G23: -2233043.5 | H23: Alacak | I23: 1540 | J23: 43452.83 | K23: -41912.83 | L23: Alacak
A24: 100.01.02.0002 | B24: Euro Kasası | C24: EUR | D24: ROYAL DRAGON | E24: 0 | F24: 514211.74 | G24: -514211.74 | H24: Alacak | I24: 0 | J24: 9675 | K24: -9675 | L24: Alacak
A25: 100.01.02.0002 | B25: Euro Kasası | C25: EUR | D25: ROYAL HOLIDAY | E25: 0 | F25: 524294.56 | G25: -524294.56 | H25: Alacak | I25: 0 | J25: 9840 | K25: -9840 | L25: Alacak
A26: 100.01.02.0002 | B26: Euro Kasası | C26: EUR | D26: ROYAL SEGINUS | E26: 465808.56 | F26: 4153038.8 | G26: -3687230.3 | H26: Alacak | I26: 8725 | J26: 77895 | K26: -69170 | L26: Alacak
A27: 100.01.02.0002 | B27: Euro Kasası | C27: EUR | D27: SERTAŞ MERKEZ | E27: 40012.89 | F27: 0 | G27: 40012.89 | H27: Borç | I27: 750 | J27: 0 | K27: 750 | L27: Borç
A28: 100.01.02.0003 | B28: Gbp Kasası | C28: GBP | D28: ROYAL ADAM EVE | E28: 0 | F28: 39087.3 | G28: -39087.3 | H28: Alacak | I28: 0 | J28: 640 | K28: -640 | L28: Alacak
A29: 100.01.02.0003 | B29: Gbp Kasası | C29: GBP | D29: ROYAL HOLIDAY | E29: 0 | F29: 95948.1 | G29: -95948.1 | H29: Alacak | I29: 0 | J29: 1550 | K29: -1550 | L29: Alacak
A30: 100.01.02.0005 | B30: Önbüro Euro Kasası | C30: EUR | D30: ROYAL ADAM EVE | E30: 2731750.1 | F30: 0 | G30: 2731750.1 | H30: Borç | I30: 51329.5 | J30: 0 | K30: 51329.5 | L30: Borç
... A42: 100.01.02.0008 | B42: Önbüro Gbp Kasası | C42: GBP | D42: ROYAL SEGINUS | E42: 22058.69 | F42: 0 | G42: 22058.69 | H42: Borç | I42: 360.12 | J42: 0 | K42: 360.12 | L42: Borç
A43: 101 | B43: ALINAN ÇEKLER | C43: TRY | E43: 16368625 | F43: 5.1965099e+08 | G43: -5.0328237e+08 | I43: 1538430 | J43: 89401719 | K43: -87863289
A44: 101.01 | B44: ALINAN ÇEKLER | C44: TRY | E44: 16368625 | F44: 5.1965099e+08 | G44: -5.0328237e+08 | I44: 1538430 | J44: 89401719 | K44: -87863289
A45: 101.01.01 | B45: PORTFOYDEKİ TL ÇEKLER | C45: TRY | E45: 1260000 | F45: 81150919 | G45: -79890919 | I45: 1260000 | J45: 81150919 | K45: -79890919
A46: 101.01.01.0004 | B46: Nisan Vadeli Alınan TL Çekler | C46: TRY | D46: ROYAL SEGINUS | E46: 0 | F46: 560000 | G46: -560000 | H46: Alacak | I46: 0 | J46: 560000 | K46: -560000 | L46: Alacak
A47: 101.01.01.0004 | B47: Nisan Vadeli Alınan TL Çekler | C47: TRY | D47: STONE ÇARŞI | E47: 560000 | F47: 560000 | G47: 0 | I47: 560000 | J47: 560000 | K47: 0
A48: 101.01.01.0005 | B48: Mayıs Vadeli Alınan TL Çekler | C48: TRY | D48: ROYAL SEGINUS | E48: 0 | F48: 700000 | G48: -700000 | H48: Alacak | I48: 0 | J48: 700000 | K48: -700000 | L48: Alacak
A49: 101.01.01.0005 | B49: Mayıs Vadeli Alınan TL Çekler | C49: TRY | D49: SERTAŞ MERKEZ | E49: 0 | F49: 816400 | G49: -816400 | H49: Alacak | I49: 0 | J49: 816400 | K49: -816400 | L49: Alacak
A50: 101.01.01.0005 | B50: Mayıs Vadeli Alınan TL Çekler | C50: TRY | D50: STONE ÇARŞI | E50: 700000 | F50: 700000 | G50: 0 | I50: 700000 | J50: 700000 | K50: 0
A51: 101.01.01.0006 | B51: Haziran Vadeli Alınan TL Çekler | C51: TRY | D51: ROYAL SEGINUS | E51: 0 | F51: 12000000 | G51: -12000000 | H51: Alacak | I51: 0 | J51: 12000000 | K51: -12000000 | L51: Alacak
...

Sheet KDV_BEYAN_ICMAL
A1: KDV BEYANNAME İCMALİ - ŞUBE ŞUBE / MERKEZLER HARİÇ
A3: Şube | B3: KDV1 Matrah %10 | C3: KDV1 Hesaplanan %10 | D3: KDV1 Matrah %20 | E3: KDV1 Hesaplanan %20 | F3: İade Matrah %10 | G3: Satıştan İade KDV %10 | H3: İade Matrah %20 | I3: Satıştan İade KDV %20 | J3: 191 İndirilecek %1 | K3: 191 İndirilecek %10 | L3: 191 İndirilecek %20 | M3: 191 Tevkifatlı | N3: 391 İlave/Alıştan İade | O3: Toplam 391 | P3: Toplam 191 | Q3: Net KDV | R3: Sonuç | S3: Beyanname Notu
A4: =KDV_HESAP_TABANI!A2 | B4: =KDV_HESAP_TABANI!B2 | C4: =KDV_HESAP_TABANI!D2 | D4: =KDV_HESAP_TABANI!G2 | E4: =KDV_HESAP_TABANI!I2 | F4: =KDV_HESAP_TABANI!L2 | G4: =KDV_HESAP_TABANI!N2 | H4: =KDV_HESAP_TABANI!Q2 | I4: =KDV_HESAP_TABANI!S2 | J4: =KDV_HESAP_TABANI!AF2 | K4: =KDV_HESAP_TABANI!AG2 | L4: =KDV_HESAP_TABANI!AH2 | M4: =KDV_HESAP_TABANI!AI2 | N4: =KDV_HESAP_TABANI!AJ2+KDV_HESAP_TABANI!AK2+KDV_HESAP_TABANI!AL2 | O4: =KDV_HESAP_TABANI!AM2 | P4: =KDV_HESAP_TABANI!AN2 | Q4: =KDV_HESAP_TABANI!AO2 | R4: =KDV_HESAP_TABANI!AP2 | S4: =IF(M4>0,"KDV2/sorumlu sıfatı varsa ayrıca teyit et; KDV1 indirim satırı da kontrol edilir","KDV1 ana beyanname icmali")
A5: =KDV_HESAP_TABANI!A3 | B5: =KDV_HESAP_TABANI!B3 | C5: =KDV_HESAP_TABANI!D3 | D5: =KDV_HESAP_TABANI!G3 | E5: =KDV_HESAP_TABANI!I3 | F5: =KDV_HESAP_TABANI!L3 | G5: =KDV_HESAP_TABANI!N3 | H5: =KDV_HESAP_TABANI!Q3 | I5: =KDV_HESAP_TABANI!S3 | J5: =KDV_HESAP_TABANI!AF3 | K5: =KDV_HESAP_TABANI!AG3 | L5: =KDV_HESAP_TABANI!AH3 | M5: =KDV_HESAP_TABANI!AI3 | N5: =KDV_HESAP_TABANI!AJ3+KDV_HESAP_TABANI!AK3+KDV_HESAP_TABANI!AL3 | O5: =KDV_HESAP_TABANI!AM3 | P5: =KDV_HESAP_TABANI!AN3 | Q5: =KDV_HESAP_TABANI!AO3 | R5: =KDV_HESAP_TABANI!AP3 | S5: =IF(M5>0,"KDV2/sorumlu sıfatı varsa ayrıca teyit et; KDV1 indirim satırı da kontrol edilir","KDV1 ana beyanname icmali")
A6: =KDV_HESAP_TABANI!A4 | B6: =KDV_HESAP_TABANI!B4 | C6: =KDV_HESAP_TABANI!D4 | D6: =KDV_HESAP_TABANI!G4 | E6: =KDV_HESAP_TABANI!I4 | F6: =KDV_HESAP_TABANI!L4 | G6: =KDV_HESAP_TABANI!N4 | H6: =KDV_HESAP_TABANI!Q4 | I6: =KDV_HESAP_TABANI!S4 | J6: =KDV_HESAP_TABANI!AF4 | K6: =KDV_HESAP_TABANI!AG4 | L6: =KDV_HESAP_TABANI!AH4 | M6: =KDV_HESAP_TABANI!AI4 | N6: =KDV_HESAP_TABANI!AJ4+KDV_HESAP_TABANI!AK4+KDV_HESAP_TABANI!AL4 | O6: =KDV_HESAP_TABANI!AM4 | P6: =KDV_HESAP_TABANI!AN4 | Q6: =KDV_HESAP_TABANI!AO4 | R6: =KDV_HESAP_TABANI!AP4 | S6: =IF(M6>0,"KDV2/sorumlu sıfatı varsa ayrıca teyit et; KDV1 indirim satırı da kontrol edilir","KDV1 ana beyanname icmali")
A7: =KDV_HESAP_TABANI!A5 | B7: =KDV_HESAP_TABANI!B5 | C7: =KDV_HESAP_TABANI!D5 | D7: =KDV_HESAP_TABANI!G5 | E7: =KDV_HESAP_TABANI!I5 | F7: =KDV_HESAP_TABANI!L5 | G7: =KDV_HESAP_TABANI!N5 | H7: =KDV_HESAP_TABANI!Q5 | I7: =KDV_HESAP_TABANI!S5 | J7: =KDV_HESAP_TABANI!AF5 | K7: =KDV_HESAP_TABANI!AG5 | L7: =KDV_HESAP_TABANI!AH5 | M7: =KDV_HESAP_TABANI!AI5 | N7: =KDV_HESAP_TABANI!AJ5+KDV_HESAP_TABANI!AK5+KDV_HESAP_TABANI!AL5 | O7: =KDV_HESAP_TABANI!AM5 | P7: =KDV_HESAP_TABANI!AN5 | Q7: =KDV_HESAP_TABANI!AO5 | R7: =KDV_HESAP_TABANI!AP5 | S7: =IF(M7>0,"KDV2/sorumlu sıfatı varsa ayrıca teyit et; KDV1 indirim satırı da kontrol edilir","KDV1 ana beyanname icmali")
A8: =KDV_HESAP_TABANI!A6 | B8: =KDV_HESAP_TABANI!B6 | C8: =KDV_HESAP_TABANI!D6 | D8: =KDV_HESAP_TABANI!G6 | E8: =KDV_HESAP_TABANI!I6 | F8: =KDV_HESAP_TABANI!L6 | G8: =KDV_HESAP_TABANI!N6 | H8: =KDV_HESAP_TABANI!Q6 | I8: =KDV_HESAP_TABANI!S6 | J8: =KDV_HESAP_TABANI!AF6 | K8: =KDV_HESAP_TABANI!AG6 | L8: =KDV_HESAP_TABANI!AH6 | M8: =KDV_HESAP_TABANI!AI6 | N8: =KDV_HESAP_TABANI!AJ6+KDV_HESAP_TABANI!AK6+KDV_HESAP_TABANI!AL6 | O8: =KDV_HESAP_TABANI!AM6 | P8: =KDV_HESAP_TABANI!AN6 | Q8: =KDV_HESAP_TABANI!AO6 | R8: =KDV_HESAP_TABANI!AP6 | S8: =IF(M8>0,"KDV2/sorumlu sıfatı varsa ayrıca teyit et; KDV1 indirim satırı da kontrol edilir","KDV1 ana beyanname icmali")
A9: =KDV_HESAP_TABANI!A7 | B9: =KDV_HESAP_TABANI!B7 | C9: =KDV_HESAP_TABANI!D7 | D9: =KDV_HESAP_TABANI!G7 | E9: =KDV_HESAP_TABANI!I7 | F9: =KDV_HESAP_TABANI!L7 | G9: =KDV_HESAP_TABANI!N7 | H9: =KDV_HESAP_TABANI!Q7 | I9: =KDV_HESAP_TABANI!S7 | J9: =KDV_HESAP_TABANI!AF7 | K9: =KDV_HESAP_TABANI!AG7 | L9: =KDV_HESAP_TABANI!AH7 | M9: =KDV_HESAP_TABANI!AI7 | N9: =KDV_HESAP_TABANI!AJ7+KDV_HESAP_TABANI!AK7+KDV_HESAP_TABANI!AL7 | O9: =KDV_HESAP_TABANI!AM7 | P9: =KDV_HESAP_TABANI!AN7 | Q9: =KDV_HESAP_TABANI!AO7 | R9: =KDV_HESAP_TABANI!AP7 | S9: =IF(M9>0,"KDV2/sorumlu sıfatı varsa ayrıca teyit et; KDV1 indirim satırı da kontrol edilir","KDV1 ana beyanname icmali")
A10: TOPLAM | B10: =SUM(B4:B9) | C10: =SUM(C4:C9) | D10: =SUM(D4:D9) | E10: =SUM(E4:E9) | F10: =SUM(F4:F9) | G10: =SUM(G4:G9) | H10: =SUM(H4:H9) | I10: =SUM(I4:I9) | ... Q10: =SUM(Q4:Q9) | R10: =IF(Q10>0,"ÖDENECEK KDV",IF(Q10<0,"DEVREDEN KDV","SIFIR")) | S10: KDV1 toplu sonuç

Sheet KDV_ORAN_KONTROL
A1: KDV ORAN / HESAP EŞLEŞME KONTROLÜ
A3: Şube | B3: Kontrol | C3: Matrah | D3: Beklenen KDV | E3: Mevcut KDV | F3: Fark | G3: Durum | H3: Beyanname | I3: Robot Açıklaması | J3: Hatalı KDV Nedeni | K3: Kontrol Edilecek Alan
A4: =KDV_HESAP_TABANI!A2 | B4: 600 %10 Gelir ↔ 391 %10 | C4: =KDV_HESAP_TABANI!B2 | D4: =KDV_HESAP_TABANI!C2 | E4: =KDV_HESAP_TABANI!D2 | F4: =KDV_HESAP_TABANI!E2 | G4: =KDV_HESAP_TABANI!F2 | H4: KDV1 | I4: 600 %10 matrah x %10 = 391 %10 hesaplanan KDV olmalı. | J4: =IFERROR(INDEX(HATA_NEDEN_MOTORU!$H$2:$H$37,MATCH(A4&B4,HATA_NEDEN_MOTORU!$A$2:$A$37&HATA_NEDEN_MOTORU!$B$2:$B$37,0)),"") | K4: =IFERROR(INDEX(HATA_NEDEN_MOTORU!$J$2:$J$37,MATCH(A4&B4,HATA_NEDEN_MOTORU!$A$2:$A$37&HATA_NEDEN_MOTORU!$B$2:$B$37,0)),"")
A5: =KDV_HESAP_TABANI!A2 | B5: 600 %20 Gelir ↔ 391 %20 | C5: =KDV_HESAP_TABANI!G2 | D5: =KDV_HESAP_TABANI!H2 | E5: =KDV_HESAP_TABANI!I2 | F5: =KDV_HESAP_TABANI!J2 | G5: =KDV_HESAP_TABANI!K2 | H5: KDV1 | I5: 600 %20 matrah x %20 = 391 %20 hesaplanan KDV olmalı. | J5: =IFERROR(INDEX(HATA_NEDEN_MOTORU!$H$2:$H$37,MATCH(A5&B5,HATA_NEDEN_MOTORU!$A$2:$A$37&HATA_NEDEN_MOTORU!$B$2:$B$37,0)),"") | K5: =IFERROR(INDEX(HATA_NEDEN_MOTORU!$J$2:$J$37,MATCH(A5&B5,HATA_NEDEN_MOTORU!$A$2:$A$37&HATA_NEDEN_MOTORU!$B$2:$B$37,0)),"")
A6: =KDV_HESAP_TABANI!A2 | B6: 610 %10 İade ↔ 191 %10 | C6: =KDV_HESAP_TABANI!L2 | D6: =KDV_HESAP_TABANI!M2 | E6: =KDV_HESAP_TABANI!N2 | F6: =KDV_HESAP_TABANI!O2 | G6: =KDV_HESAP_TABANI!P2 | H6: KDV1 | I6: Satış iadesi KDV etkisi 191 satıştan iade hesabında görülmeli. | J6: =IFERROR(INDEX(HATA_NEDEN_MOTORU!$H$2:$H$37,MATCH(A6&B6,HATA_NEDEN_MOTORU!$A$2:$A$37&HATA_NEDEN_MOTORU!$B$2:$B$37,0)),"") | K6: =IFERROR(INDEX(HATA_NEDEN_MOTORU!$J$2:$J$37,MATCH(A6&B6,HATA_NEDEN_MOTORU!$A$2:$A$37&HATA_NEDEN_MOTORU!$B$2:$B$37,0)),"")
A7: =KDV_HESAP_TABANI!A2 | B7: 610 %20 İade ↔ 191 %20 | C7: =KDV_HESAP_TABANI!Q2 | D7: =KDV_HESAP_TABANI!R2 | E7: =KDV_HESAP_TABANI!S2 | F7: =KDV_HESAP_TABANI!T2 | G7: =KDV_HESAP_TABANI!U2 | H7: KDV1 | I7: %20 satış iadesi için 191 satıştan iade KDV kontrol edilir. | J7: =IFERROR(INDEX(HATA_NEDEN_MOTORU!$H$2:$H$37,MATCH(A7&B7,HATA_NEDEN_MOTORU!$A$2:$A$37&HATA_NEDEN_MOTORU!$B$2:$B$37,0)),"") | K7: =IFERROR(INDEX(HATA_NEDEN_MOTORU!$J$2:$J$37,MATCH(A7&B7,HATA_NEDEN_MOTORU!$A$2:$A$37&HATA_NEDEN_MOTORU!$B$2:$B$37,0)),"")
A8: =KDV_HESAP_TABANI!A2 | B8: 602 %20 Ciro/İskonto ↔ 391 İlave | C8: =KDV_HESAP_TABANI!V2 | D8: =KDV_HESAP_TABANI!W2 | E8: =KDV_HESAP_TABANI!X2 | F8: =KDV_HESAP_TABANI!Y2 | G8: =KDV_HESAP_TABANI!Z2 | H8: KDV1 | I8: Alış iskonto/ciro primi vb. ilave KDV 391 tarafında izlenir. | J8: =IFERROR(INDEX(HATA_NEDEN_MOTORU!$H$2:$H$37,MATCH(A8&B8,HATA_NEDEN_MOTORU!$A$2:$A$37&HATA_NEDEN_MOTORU!$B$2:$B$37,0)),"") | K8: =IFERROR(INDEX(HATA_NEDEN_MOTORU!$J$2:$J$37,MATCH(A8&B8,HATA_NEDEN_MOTORU!$A$2:$A$37&HATA_NEDEN_MOTORU!$B$2:$B$37,0)),"")
A9: =KDV_HESAP_TABANI!A2 | B9: 646 %10 Kur Kârı ↔ 391 İlave | C9: =KDV_HESAP_TABANI!AA2 | D9: =KDV_HESAP_TABANI!AB2 | E9: =KDV_HESAP_TABANI!AC2 | F9: =KDV_HESAP_TABANI!AD2 | G9: =KDV_HESAP_TABANI!AE2 | H9: KDV1 | I9: KDV hesaplanan kur farkı/ilave KDV 391 ilave KDV ile uyumlu olmalı. | J9: =IFERROR(INDEX(HATA_NEDEN_MOTORU!$H$2:$H$37,MATCH(A9&B9,HATA_NEDEN_MOTORU!$A$2:$A$37&HATA_NEDEN_MOTORU!$B$2:$B$37,0)),"") | K9: =IFERROR(INDEX(HATA_NEDEN_MOTORU!$J$2:$J$37,MATCH(A9&B9,HATA_NEDEN_MOTORU!$A$2:$A$37&HATA_NEDEN_MOTORU!$B$2:$B$37,0)),"")
A10: =KDV_HESAP_TABANI!A3 | B10: 600 %10 Gelir ↔ 391 %10 | C10: =KDV_HESAP_TABANI!B3 | D10: =KDV_HESAP_TABANI!C3 | E10: =KDV_HESAP_TABANI!D3 | F10: =KDV_HESAP_TABANI!E3 | G10: =KDV_HESAP_TABANI!F3 | H10: KDV1 | I10: 600 %10 matrah x %10 = 391 %10 hesaplanan KDV olmalı. | J10: =IFERROR(INDEX(HATA_NEDEN_MOTORU!$H$2:$H$37,MATCH(A10&B10,HATA_NEDEN_MOTORU!$A$2:$A$37&HATA_NEDEN_MOTORU!$B$2:$B$37,0)),"") | K10: =IFERROR(INDEX(HATA_NEDEN_MOTORU!$J$2:$J$37,MATCH(A10&B10,HATA_NEDEN_MOTORU!$A$2:$A$37&HATA_NEDEN_MOTORU!$B$2:$B$37,0)),"")
A11: =KDV_HESAP_TABANI!A3 | B11: 600 %20 Gelir ↔ 391 %20 | C11: =KDV_HESAP_TABANI!G3 | D11: =KDV_HESAP_TABANI!H3 | E11: =KDV_HESAP_TABANI!I3 | F11: =KDV_HESAP_TABANI!J3 | G11: =KDV_HESAP_TABANI!K3 | H11: KDV1 | I11: 600 %20 matrah x %20 = 391 %20 hesaplanan KDV olmalı. | J11: =IFERROR(INDEX(HATA_NEDEN_MOTORU!$H$2:$H$37,MATCH(A11&B11,HATA_NEDEN_MOTORU!$A$2:$A$37&HATA_NEDEN_MOTORU!$B$2:$B$37,0)),"") | K11: =IFERROR(INDEX(HATA_NEDEN_MOTORU!$J$2:$J$37,MATCH(A11&B11,HATA_NEDEN_MOTORU!$A$2:$A$37&HATA_NEDEN_MOTORU!$B$2:$B$37,0)),"")
A12: =KDV_HESAP_TABANI!A3 | B12: 610 %10 İade ↔ 191 %10 | C12: =KDV_HESAP_TABANI!L3 | D12: =KDV_HESAP_TABANI!M3 | E12: =KDV_HESAP_TABANI!N3 | F12: =KDV_HESAP_TABANI!O3 | G12: =KDV_HESAP_TABANI!P3 | H12: KDV1 | I12: Satış iadesi KDV etkisi 191 satıştan iade hesabında görülmeli. | J12: =IFERROR(INDEX(HATA_NEDEN_MOTORU!$H$2:$H$37,MATCH(A12&B12,HATA_NEDEN_MOTORU!$A$2:$A$37&HATA_NEDEN_MOTORU!$B$2:$B$37,0)),"") | K12: =IFERROR(INDEX(HATA_NEDEN_MOTORU!$J$2:$J$37,MATCH(A12&B12,HATA_NEDEN_MOTORU!$A$2:$A$37&HATA_NEDEN_MOTORU!$B$2:$B$37,0)),"")
A13: =KDV_HESAP_TABANI!A3 | B13: 610 %20 İade ↔ 191 %20 | C13: =KDV_HESAP_TABANI!Q3 | D13: =KDV_HESAP_TABANI!R3 | E13: =KDV_HESAP_TABANI!S3 | F13: =KDV_HESAP_TABANI!T3 | G13: =KDV_HESAP_TABANI!U3 | H13: KDV1 | I13: %20 satış iadesi için 191 satıştan iade KDV kontrol edilir. | J13: =IFERROR(INDEX(HATA_NEDEN_MOTORU!$H$2:$H$37,MATCH(A13&B13,HATA_NEDEN_MOTORU!$A$2:$A$37&HATA_NEDEN_MOTORU!$B$2:$B$37,0)),"") | K13: =IFERROR(INDEX(HATA_NEDEN_MOTORU!$J$2:$J$37,MATCH(A13&B13,HATA_NEDEN_MOTORU!$A$2:$A$37&HATA_NEDEN_MOTORU!$B$2:$B$37,0)),"")
A14: =KDV_HESAP_TABANI!A3 | B14: 602 %20 Ciro/İskonto ↔ 391 İlave | C14: =KDV_HESAP_TABANI!V3 | D14: =KDV_HESAP_TABANI!W3 | E14: =KDV_HESAP_TABANI!X3 | F14: =KDV_HESAP_TABANI!Y3 | G14: =KDV_HESAP_TABANI!Z3 | H14: KDV1 | I14: Alış iskonto/ciro primi vb. ilave KDV 391 tarafında izlenir. | J14: =IFERROR(INDEX(HATA_NEDEN_MOTORU!$H$2:$H$37,MATCH(A14&B14,HATA_NEDEN_MOTORU!$A$2:$A$37&HATA_NEDEN_MOTORU!$B$2:$B$37,0)),"") | K14: =IFERROR(INDEX(HATA_NEDEN_MOTORU!$J$2:$J$37,MATCH(A14&B14,HATA_NEDEN_MOTORU!$A$2:$A$37&HATA_NEDEN_MOTORU!$B$2:$B$37,0)),"")
A15: =KDV_HESAP_TABANI!A3 | B15: 646 %10 Kur Kârı ↔ 391 İlave | C15: =KDV_HESAP_TABANI!AA3 | D15: =KDV_HESAP_TABANI!AB3 | E15: =KDV_HESAP_TABANI!AC3 | F15: =KDV_HESAP_TABANI!AD3 | G15: =KDV_HESAP_TABANI!AE3 | H15: KDV1 | I15: KDV hesaplanan kur farkı/ilave KDV 391 ilave KDV ile uyumlu olmalı. | J15: =IFERROR(INDEX(HATA_NEDEN_MOTORU!$H$2:$H$37,MATCH(A15&B15,HATA_NEDEN_MOTORU!$A$2:$A$37&HATA_NEDEN_MOTORU!$B$2:$B$37,0)),"") | K15: =IFERROR(INDEX(HATA_NEDEN_MOTORU!$J$2:$J$37,MATCH(A15&B15,HATA_NEDEN_MOTORU!$A$2:$A$37&HATA_NEDEN_MOTORU!$B$2:$B$37,0)),"")
A16: =KDV_HESAP_TABANI!A4 | B16: 600 %10 Gelir ↔ 391 %10 | C16: =KDV_HESAP_TABANI!B4 | D16: =KDV_HESAP_TABANI!C4 | E16: =KDV_HESAP_TABANI!D4 | F16: =KDV_HESAP_TABANI!E4 | G16: =KDV_HESAP_TABANI!F4 | H16: KDV1 | I16: 600 %10 matrah x %10 = 391 %10 hesaplanan KDV olmalı. | J16: =IFERROR(INDEX(HATA_NEDEN_MOTORU!$H$2:$H$37,MATCH(A16&B16,HATA_NEDEN_MOTORU!$A$2:$A$37&HATA_NEDEN_MOTORU!$B$2:$B$37,0)),"") | K16: =IFERROR(INDEX(HATA_NEDEN_MOTORU!$J$2:$J$37,MATCH(A16&B16,HATA_NEDEN_MOTORU!$A$2:$A$37&HATA_NEDEN_MOTORU!$B$2:$B$37,0)),"")
A17: =KDV_HESAP_TABANI!A4 | B17: 600 %20 Gelir ↔ 391 %20 | C17: =KDV_HESAP_TABANI!G4 | D17: =KDV_HESAP_TABANI!H4 | E17: =KDV_HESAP_TABANI!I4 | F17: =KDV_HESAP_TABANI!J4 | G17: =KDV_HESAP_TABANI!K4 | H17: KDV1 | I17: 600 %20 matrah x %20 = 391 %20 hesaplanan KDV olmalı. | J17: =IFERROR(INDEX(HATA_NEDEN_MOTORU!$H$2:$H$37,MATCH(A17&B17,HATA_NEDEN_MOTORU!$A$2:$A$37&HATA_NEDEN_MOTORU!$B$2:$B$37,0)),"") | K17: =IFERROR(INDEX(HATA_NEDEN_MOTORU!$J$2:$J$37,MATCH(A17&B17,HATA_NEDEN_MOTORU!$A$2:$A$37&HATA_NEDEN_MOTORU!$B$2:$B$37,0)),"")
A18: =KDV_HESAP_TABANI!A4 | B18: 610 %10 İade ↔ 191 %10 | C18: =KDV_HESAP_TABANI!L4 | D18: =KDV_HESAP_TABANI!M4 | E18: =KDV_HESAP_TABANI!N4 | F18: =KDV_HESAP_TABANI!O4 | G18: =KDV_HESAP_TABANI!P4 | H18: KDV1 | I18: Satış iadesi KDV etkisi 191 satıştan iade hesabında görülmeli. | J18: =IFERROR(INDEX(HATA_NEDEN_MOTORU!$H$2:$H$37,MATCH(A18&B18,HATA_NEDEN_MOTORU!$A$2:$A$37&HATA_NEDEN_MOTORU!$B$2:$B$37,0)),"") | K18: =IFERROR(INDEX(HATA_NEDEN_MOTORU!$J$2:$J$37,MATCH(A18&B18,HATA_NEDEN_MOTORU!$A$2:$A$37&HATA_NEDEN_MOTORU!$B$2:$B$37,0)),"")
A19: =KDV_HESAP_TABANI!A4 | B19: 610 %20 İade ↔ 191 %20 | C19: =KDV_HESAP_TABANI!Q4 | D19: =KDV_HESAP_TABANI!R4 | E19: =KDV_HESAP_TABANI!S4 | F19: =KDV_HESAP_TABANI!T4 | G19: =KDV_HESAP_TABANI!U4 | H19: KDV1 | I19: %20 satış iadesi için 191 satıştan iade KDV kontrol edilir. | J19: =IFERROR(INDEX(HATA_NEDEN_MOTORU!$H$2:$H$37,MATCH(A19&B19,HATA_NEDEN_MOTORU!$A$2:$A$37&HATA_NEDEN_MOTORU!$B$2:$B$37,0)),"") | K19: =IFERROR(INDEX(HATA_NEDEN_MOTORU!$J$2:$J$37,MATCH(A19&B19,HATA_NEDEN_MOTORU!$A$2:$A$37&HATA_NEDEN_MOTORU!$B$2:$B$37,0)),"")
A20: =KDV_HESAP_TABANI!A4 | B20: 602 %20 Ciro/İskonto ↔ 391 İlave | C20: =KDV_HESAP_TABANI!V4 | D20: =KDV_HESAP_TABANI!W4 | E20: =KDV_HESAP_TABANI!X4 | F20: =KDV_HESAP_TABANI!Y4 | G20: =KDV_HESAP_TABANI!Z4 | H20: KDV1 | I20: Alış iskonto/ciro primi vb. ilave KDV 391 tarafında izlenir. | J20: =IFERROR(INDEX(HATA_NEDEN_MOTORU!$H$2:$H$37,MATCH(A20&B20,HATA_NEDEN_MOTORU!$A$2:$A$37&HATA_NEDEN_MOTORU!$B$2:$B$37,0)),"") | K20: =IFERROR(INDEX(HATA_NEDEN_MOTORU!$J$2:$J$37,MATCH(A20&B20,HATA_NEDEN_MOTORU!$A$2:$A$37&HATA_NEDEN_MOTORU!$B$2:$B$37,0)),"")
A21: =KDV_HESAP_TABANI!A4 | B21: 646 %10 Kur Kârı ↔ 391 İlave | C21: =KDV_HESAP_TABANI!AA4 | D21: =KDV_HESAP_TABANI!AB4 | E21: =KDV_HESAP_TABANI!AC4 | F21: =KDV_HESAP_TABANI!AD4 | G21: =KDV_HESAP_TABANI!AE4 | H21: KDV1 | I21: KDV hesaplanan kur farkı/ilave KDV 391 ilave KDV ile uyumlu olmalı. | J21: =IFERROR(INDEX(HATA_NEDEN_MOTORU!$H$2:$H$37,MATCH(A21&B21,HATA_NEDEN_MOTORU!$A$2:$A$37&HATA_NEDEN_MOTORU!$B$2:$B$37,0)),"") | K21: =IFERROR(INDEX(HATA_NEDEN_MOTORU!$J$2:$J$37,MATCH(A21&B21,HATA_NEDEN_MOTORU!$A$2:$A$37&HATA_NEDEN_MOTORU!$B$2:$B$37,0)),"")
A22: =KDV_HESAP_TABANI!A5 | B22: 600 %10 Gelir ↔ 391 %10 | C22: =KDV_HESAP_TABANI!B5 | D22: =KDV_HESAP_TABANI!C5 | E22: =KDV_HESAP_TABANI!D5 | F22: =KDV_HESAP_TABANI!E5 | G22: =KDV_HESAP_TABANI!F5 | H22: KDV1 | I22: 600 %10 matrah x %10 = 391 %10 hesaplanan KDV olmalı. | J22: =IFERROR(INDEX(HATA_NEDEN_MOTORU!$H$2:$H$37,MATCH(A22&B22,HATA_NEDEN_MOTORU!$A$2:$A$37&HATA_NEDEN_MOTORU!$B$2:$B$37,0)),"") | K22: =IFERROR(INDEX(HATA_NEDEN_MOTORU!$J$2:$J$37,MATCH(A22&B22,HATA_NEDEN_MOTORU!$A$2:$A$37&HATA_NEDEN_MOTORU!$B$2:$B$37,0)),"")
A23: =KDV_HESAP_TABANI!A5 | B23: 600 %20 Gelir ↔ 391 %20 | C23: =KDV_HESAP_TABANI!G5 | D23: =KDV_HESAP_TABANI!H5 | E23: =KDV_HESAP_TABANI!I5 | F23: =KDV_HESAP_TABANI!J5 | G23: =KDV_HESAP_TABANI!K5 | H23: KDV1 | I23: 600 %20 matrah x %20 = 391 %20 hesaplanan KDV olmalı. | J23: =IFERROR(INDEX(HATA_NEDEN_MOTORU!$H$2:$H$37,MATCH(A23&B23,HATA_NEDEN_MOTORU!$A$2:$A$37&HATA_NEDEN_MOTORU!$B$2:$B$37,0)),"") | K23: =IFERROR(INDEX(HATA_NEDEN_MOTORU!$J$2:$J$37,MATCH(A23&B23,HATA_NEDEN_MOTORU!$A$2:$A$37&HATA_NEDEN_MOTORU!$B$2:$B$37,0)),"")
A24: =KDV_HESAP_TABANI!A5 | B24: 610 %10 İade ↔ 191 %10 | C24: =KDV_HESAP_TABANI!L5 | D24: =KDV_HESAP_TABANI!M5 | E24: =KDV_HESAP_TABANI!N5 | F24: =KDV_HESAP_TABANI!O5 | G24: =KDV_HESAP_TABANI!P5 | H24: KDV1 | I24: Satış iadesi KDV etkisi 191 satıştan iade hesabında görülmeli. | J24: =IFERROR(INDEX(HATA_NEDEN_MOTORU!$H$2:$H$37,MATCH(A24&B24,HATA_NEDEN_MOTORU!$A$2:$A$37&HATA_NEDEN_MOTORU!$B$2:$B$37,0)),"") | K24: =IFERROR(INDEX(HATA_NEDEN_MOTORU!$J$2:$J$37,MATCH(A24&B24,HATA_NEDEN_MOTORU!$A$2:$A$37&HATA_NEDEN_MOTORU!$B$2:$B$37,0)),"")
A25: =KDV_HESAP_TABANI!A5 | B25: 610 %20 İade ↔ 191 %20 | C25: =KDV_HESAP_TABANI!Q5 | D25: =KDV_HESAP_TABANI!R5 | E25: =KDV_HESAP_TABANI!S5 | F25: =KDV_HESAP_TABANI!T5 | G25: =KDV_HESAP_TABANI!U5 | H25: KDV1 | I25: %20 satış iadesi için 191 satıştan iade KDV kontrol edilir. | J25: =IFERROR(INDEX(HATA_NEDEN_MOTORU!$H$2:$H$37,MATCH(A25&B25,HATA_NEDEN_MOTORU!$A$2:$A$37&HATA_NEDEN_MOTORU!$B$2:$B$37,0)),"") | K25: =IFERROR(INDEX(HATA_NEDEN_MOTORU!$J$2:$J$37,MATCH(A25&B25,HATA_NEDEN_MOTORU!$A$2:$A$37&HATA_NEDEN_MOTORU!$B$2:$B$37,0)),"")
A26: =KDV_HESAP_TABANI!A5 | B26: 602 %20 Ciro/İskonto ↔ 391 İlave | C26: =KDV_HESAP_TABANI!V5 | D26: =KDV_HESAP_TABANI!W5 | E26: =KDV_HESAP_TABANI!X5 | F26: =KDV_HESAP_TABANI!Y5 | G26: =KDV_HESAP_TABANI!Z5 | H26: KDV1 | I26: Alış iskonto/ciro primi vb. ilave KDV 391 tarafında izlenir. | J26: =IFERROR(INDEX(HATA_NEDEN_MOTORU!$H$2:$H$37,MATCH(A26&B26,HATA_NEDEN_MOTORU!$A$2:$A$37&HATA_NEDEN_MOTORU!$B$2:$B$37,0)),"") | K26: =IFERROR(INDEX(HATA_NEDEN_MOTORU!$J$2:$J$37,MATCH(A26&B26,HATA_NEDEN_MOTORU!$A$2:$A$37&HATA_NEDEN_MOTORU!$B$2:$B$37,0)),"")
A27: =KDV_HESAP_TABANI!A5 | B27: 646 %10 Kur Kârı ↔ 391 İlave | C27: =KDV_HESAP_TABANI!AA5 | D27: =KDV_HESAP_TABANI!AB5 | E27: =KDV_HESAP_TABANI!AC5 | F27: =KDV_HESAP_TABANI!AD5 | G27: =KDV_HESAP_TABANI!AE5 | H27: KDV1 | I27: KDV hesaplanan kur farkı/ilave KDV 391 ilave KDV ile uyumlu olmalı. | J27: =IFERROR(INDEX(HATA_NEDEN_MOTORU!$H$2:$H$37,MATCH(A27&B27,HATA_NEDEN_MOTORU!$A$2:$A$37&HATA_NEDEN_MOTORU!$B$2:$B$37,0)),"") | K27: =IFERROR(INDEX(HATA_NEDEN_MOTORU!$J$2:$J$37,MATCH(A27&B27,HATA_NEDEN_MOTORU!$A$2:$A$37&HATA_NEDEN_MOTORU!$B$2:$B$37,0)),"")
A28: =KDV_HESAP_TABANI!A6 | B28: 600 %10 Gelir ↔ 391 %10 | C28: =KDV_HESAP_TABANI!B6 | D28: =KDV_HESAP_TABANI!C6 | E28: =KDV_HESAP_TABANI!D6 | F28: =KDV_HESAP_TABANI!E6 | G28: =KDV_HESAP_TABANI!F6 | H28: KDV1 | I28: 600 %10 matrah x %10 = 391 %10 hesaplanan KDV olmalı. | J28: =IFERROR(INDEX(HATA_NEDEN_MOTORU!$H$2:$H$37,MATCH(A28&B28,HATA_NEDEN_MOTORU!$A$2:$A$37&HATA_NEDEN_MOTORU!$B$2:$B$37,0)),"") | K28: =IFERROR(INDEX(HATA_NEDEN_MOTORU!$J$2:$J$37,MATCH(A28&B28,HATA_NEDEN_MOTORU!$A$2:$A$37&HATA_NEDEN_MOTORU!$B$2:$B$37,0)),"")
A29: =KDV_HESAP_TABANI!A6 | B29: 600 %20 Gelir ↔ 391 %20 | C29: =KDV_HESAP_TABANI!G6 | D29: =KDV_HESAP_TABANI!H6 | E29: =KDV_HESAP_TABANI!I6 | F29: =KDV_HESAP_TABANI!J6 | G29: =KDV_HESAP_TABANI!K6 | H29: KDV1 | I29: 600 %20 matrah x %20 = 391 %20 hesaplanan KDV olmalı. | J29: =IFERROR(INDEX(HATA_NEDEN_MOTORU!$H$2:$H$37,MATCH(A29&B29,HATA_NEDEN_MOTORU!$A$2:$A$37&HATA_NEDEN_MOTORU!$B$2:$B$37,0)),"") | K29: =IFERROR(INDEX(HATA_NEDEN_MOTORU!$J$2:$J$37,MATCH(A29&B29,HATA_NEDEN_MOTORU!$A$2:$A$37&HATA_NEDEN_MOTORU!$B$2:$B$37,0)),"")
A30: =KDV_HESAP_TABANI!A6 | B30: 610 %10 İade ↔ 191 %10 | C30: =KDV_HESAP_TABANI!L6 | D30: =KDV_HESAP_TABANI!M6 | E30: =KDV_HESAP_TABANI!N6 | F30: =KDV_HESAP_TABANI!O6 | G30: =KDV_HESAP_TABANI!P6 | H30: KDV1 | I30: Satış iadesi KDV etkisi 191 satıştan iade hesabında görülmeli. | J30: =IFERROR(INDEX(HATA_NEDEN_MOTORU!$H$2:$H$37,MATCH(A30&B30,HATA_NEDEN_MOTORU!$A$2:$A$37&HATA_NEDEN_MOTORU!$B$2:$B$37,0)),"") | K30: =IFERROR(INDEX(HATA_NEDEN_MOTORU!$J$2:$J$37,MATCH(A30&B30,HATA_NEDEN_MOTORU!$A$2:$A$37&HATA_NEDEN_MOTORU!$B$2:$B$37,0)),"")
A31: =KDV_HESAP_TABANI!A6 | B31: 610 %20 İade ↔ 191 %20 | C31: =KDV_HESAP_TABANI!Q6 | D31: =KDV_HESAP_TABANI!R6 | E31: =KDV_HESAP_TABANI!S6 | F31: =KDV_HESAP_TABANI!T6 | G31: =KDV_HESAP_TABANI!U6 | H31: KDV1 | I31: %20 satış iadesi için 191 satıştan iade KDV kontrol edilir. | J31: =IFERROR(INDEX(HATA_NEDEN_MOTORU!$H$2:$H$37,MATCH(A31&B31,HATA_NEDEN_MOTORU!$A$2:$A$37&HATA_NEDEN_MOTORU!$B$2:$B$37,0)),"") | K31: =IFERROR(INDEX(HATA_NEDEN_MOTORU!$J$2:$J$37,MATCH(A31&B31,HATA_NEDEN_MOTORU!$A$2:$A$37&HATA_NEDEN_MOTORU!$B$2:$B$37,0)),"")
A32: =KDV_HESAP_TABANI!A6 | B32: 602 %20 Ciro/İskonto ↔ 391 İlave | C32: =KDV_HESAP_TABANI!V6 | D32: =KDV_HESAP_TABANI!W6 | E32: =KDV_HESAP_TABANI!X6 | F32: =KDV_HESAP_TABANI!Y6 | G32: =KDV_HESAP_TABANI!Z6 | H32: KDV1 | I32: Alış iskonto/ciro primi vb. ilave KDV 391 tarafında izlenir. | J32: =IFERROR(INDEX(HATA_NEDEN_MOTORU!$H$2:$H$37,MATCH(A32&B32,HATA_NEDEN_MOTORU!$A$2:$A$37&HATA_NEDEN_MOTORU!$B$2:$B$37,0)),"") | K32: =IFERROR(INDEX(HATA_NEDEN_MOTORU!$J$2:$J$37,MATCH(A32&B32,HATA_NEDEN_MOTORU!$A$2:$A$37&HATA_NEDEN_MOTORU!$B$2:$B$37,0)),"")
A33: =KDV_HESAP_TABANI!A6 | B33: 646 %10 Kur Kârı ↔ 391 İlave | C33: =KDV_HESAP_TABANI!AA6 | D33: =KDV_HESAP_TABANI!AB6 | E33: =KDV_HESAP_TABANI!AC6 | F33: =KDV_HESAP_TABANI!AD6 | G33: =KDV_HESAP_TABANI!AE6 | H33: KDV1 | I33: KDV hesaplanan kur farkı/ilave KDV 391 ilave KDV ile uyumlu olmalı. | J33: =IFERROR(INDEX(HATA_NEDEN_MOTORU!$H$2:$H$37,MATCH(A33&B33,HATA_NEDEN_MOTORU!$A$2:$A$37&HATA_NEDEN_MOTORU!$B$2:$B$37,0)),"") | K33: =IFERROR(INDEX(HATA_NEDEN_MOTORU!$J$2:$J$37,MATCH(A33&B33,HATA_NEDEN_MOTORU!$A$2:$A$37&HATA_NEDEN_MOTORU!$B$2:$B$37,0)),"")
A34: =KDV_HESAP_TABANI!A7 | B34: 600 %10 Gelir ↔ 391 %10 | C34: =KDV_HESAP_TABANI!B7 | D34: =KDV_HESAP_TABANI!C7 | E34: =KDV_HESAP_TABANI!D7 | F34: =KDV_HESAP_TABANI!E7 | G34: =KDV_HESAP_TABANI!F7 | H34: KDV1 | I34: 600 %10 matrah x %10 = 391 %10 hesaplanan KDV olmalı. | J34: =IFERROR(INDEX(HATA_NEDEN_MOTORU!$H$2:$H$37,MATCH(A34&B34,HATA_NEDEN_MOTORU!$A$2:$A$37&HATA_NEDEN_MOTORU!$B$2:$B$37,0)),"") | K34: =IFERROR(INDEX(HATA_NEDEN_MOTORU!$J$2:$J$37,MATCH(A34&B34,HATA_NEDEN_MOTORU!$A$2:$A$37&HATA_NEDEN_MOTORU!$B$2:$B$37,0)),"")
A35: =KDV_HESAP_TABANI!A7 | B35: 600 %20 Gelir ↔ 391 %20 | C35: =KDV_HESAP_TABANI!G7 | D35: =KDV_HESAP_TABANI!H7 | E35: =KDV_HESAP_TABANI!I7 | F35: =KDV_HESAP_TABANI!J7 | G35: =KDV_HESAP_TABANI!K7 | H35: KDV1 | I35: 600 %20 matrah x %20 = 391 %20 hesaplanan KDV olmalı. | J35: =IFERROR(INDEX(HATA_NEDEN_MOTORU!$H$2:$H$37,MATCH(A35&B35,HATA_NEDEN_MOTORU!$A$2:$A$37&HATA_NEDEN_MOTORU!$B$2:$B$37,0)),"") | K35: =IFERROR(INDEX(HATA_NEDEN_MOTORU!$J$2:$J$37,MATCH(A35&B35,HATA_NEDEN_MOTORU!$A$2:$A$37&HATA_NEDEN_MOTORU!$B$2:$B$37,0)),"")
A36: =KDV_HESAP_TABANI!A7 | B36: 610 %10 İade ↔ 191 %10 | C36: =KDV_HESAP_TABANI!L7 | D36: =KDV_HESAP_TABANI!M7 | E36: =KDV_HESAP_TABANI!N7 | F36: =KDV_HESAP_TABANI!O7 | G36: =KDV_HESAP_TABANI!P7 | H36: KDV1 | I36: Satış iadesi KDV etkisi 191 satıştan iade hesabında görülmeli. | J36: =IFERROR(INDEX(HATA_NEDEN_MOTORU!$H$2:$H$37,MATCH(A36&B36,HATA_NEDEN_MOTORU!$A$2:$A$37&HATA_NEDEN_MOTORU!$B$2:$B$37,0)),"") | K36: =IFERROR(INDEX(HATA_NEDEN_MOTORU!$J$2:$J$37,MATCH(A36&B36,HATA_NEDEN_MOTORU!$A$2:$A$37&HATA_NEDEN_MOTORU!$B$2:$B$37,0)),"")
A37: =KDV_HESAP_TABANI!A7 | B37: 610 %20 İade ↔ 191 %20 | C37: =KDV_HESAP_TABANI!Q7 | D37: =KDV_HESAP_TABANI!R7 | E37: =KDV_HESAP_TABANI!S7 | F37: =KDV_HESAP_TABANI!T7 | G37: =KDV_HESAP_TABANI!U7 | H37: KDV1 | I37: %20 satış iadesi için 191 satıştan iade KDV kontrol edilir. | J37: =IFERROR(INDEX(HATA_NEDEN_MOTORU!$H$2:$H$37,MATCH(A37&B37,HATA_NEDEN_MOTORU!$A$2:$A$37&HATA_NEDEN_MOTORU!$B$2:$B$37,0)),"") | K37: =IFERROR(INDEX(HATA_NEDEN_MOTORU!$J$2:$J$37,MATCH(A37&B37,HATA_NEDEN_MOTORU!$A$2:$A$37&HATA_NEDEN_MOTORU!$B$2:$B$37,0)),"")
A38: =KDV_HESAP_TABANI!A7 | B38: 602 %20 Ciro/İskonto ↔ 391 İlave | C38: =KDV_HESAP_TABANI!V7 | D38: =KDV_HESAP_TABANI!W7 | E38: =KDV_HESAP_TABANI!X7 | F38: =KDV_HESAP_TABANI!Y7 | G38: =KDV_HESAP_TABANI!Z7 | H38: KDV1 | I38: Alış iskonto/ciro primi vb. ilave KDV 391 tarafında izlenir. | J38: =IFERROR(INDEX(HATA_NEDEN_MOTORU!$H$2:$H$37,MATCH(A38&B38,HATA_NEDEN_MOTORU!$A$2:$A$37&HATA_NEDEN_MOTORU!$B$2:$B$37,0)),"") | K38: =IFERROR(INDEX(HATA_NEDEN_MOTORU!$J$2:$J$37,MATCH(A38&B38,HATA_NEDEN_MOTORU!$A$2:$A$37&HATA_NEDEN_MOTORU!$B$2:$B$37,0)),"")
A39: =KDV_HESAP_TABANI!A7 | B39: 646 %10 Kur Kârı ↔ 391 İlave | C39: =KDV_HESAP_TABANI!AA7 | D39: =KDV_HESAP_TABANI!AB7 | E39: =KDV_HESAP_TABANI!AC7 | F39: =KDV_HESAP_TABANI!AD7 | G39: =KDV_HESAP_TABANI!AE7 | H39: KDV1 | I39: KDV hesaplanan kur farkı/ilave KDV 391 ilave KDV ile uyumlu olmalı. | J39: =IFERROR(INDEX(HATA_NEDEN_MOTORU!$H$2:$H$37,MATCH(A39&B39,HATA_NEDEN_MOTORU!$A$2:$A$37&HATA_NEDEN_MOTORU!$B$2:$B$37,0)),"") | K39: =IFERROR(INDEX(HATA_NEDEN_MOTORU!$J$2:$J$37,MATCH(A39&B39,HATA_NEDEN_MOTORU!$A$2:$A$37&HATA_NEDEN_MOTORU!$B$2:$B$37,0)),"")

Sheet HATA_NEDEN_MOTORU
A1: Şube | B1: Kontrol | C1: Matrah | D1: Beklenen KDV | E1: Mevcut KDV | F1: Fark | G1: Durum | H1: Hatalı KDV Nedeni | I1: Beyanname | J1: Kontrol Edilecek Fiş/Hesap
A2: =KDV_HESAP_TABANI!A2 | B2: 600 %10 Gelir ↔ 391 %10 | C2: =KDV_HESAP_TABANI!B2 | D2: =KDV_HESAP_TABANI!C2 | E2: =KDV_HESAP_TABANI!D2 | F2: =KDV_HESAP_TABANI!E2 | G2: =KDV_HESAP_TABANI!F2 | H2: =IF(G2="HAREKET YOK","Hareket yok",IF(G2="TUTUYOR","Tolerans içinde",IF(B2="600 %10 Gelir ↔ 391 %10",IF(F2>0,"391 %10 fazla: %20 olması gereken matrah %10 gelirde kalmış / çift KDV / mapping hatası olabilir","391 %10 eksik: gelir 391 KDV hesabına eksik aktarılmış olabilir"),IF(B2="600 %20 Gelir ↔ 391 %20",IF(F2>0,"391 %20 fazla: KDV mükerrer veya fazla tahakkuk etmiş olabilir","391 %20 eksik: %20 gelir 391 hesabına eksik aktarılmış olabilir"),IF(B2="610 %10 İade ↔ 191 %10",IF(F2>0,"191 satış iade KDV fazla: iade KDV mükerrer/manuel fazla olabilir","191 satış iade KDV eksik: iade fişi 191 hesabına bağlanmamış olabilir"),IF(B2="610 %20 İade ↔ 191 %20",IF(F2>0,"191 %20 iade KDV fazla olabilir","191 %20 iade KDV eksik olabilir"),IF(B2="602 %20 Ciro/İskonto ↔ 391 İlave",IF(F2>0,"391 ilave KDV fazla: alış iade/ciro primi mapping kontrol","391 ilave KDV eksik: alış iade/ciro primi mapping kontrol"),IF(B2="646 %10 Kur Kârı ↔ 391 İlave",IF(F2>0,"391 ilave KDV fazla: kur farkı KDV oran/hesap eşleşmesi kontrol","391 ilave KDV eksik: kur farkı KDV mapping kontrol"),"Kontrol tanımı dışı")))))))) | I2: KDV1 | J2: 600/391 gelir entegrasyon fişi ve ürün-KDV oran mapping
A3: =KDV_HESAP_TABANI!A2 | B3: 600 %20 Gelir ↔ 391 %20 | C3: =KDV_HESAP_TABANI!G2 | D3: =KDV_HESAP_TABANI!H2 | E3: =KDV_HESAP_TABANI!I2 | F3: =KDV_HESAP_TABANI!J2 | G3: =KDV_HESAP_TABANI!K2 | H3: =IF(G3="HAREKET YOK","Hareket yok",IF(G3="TUTUYOR","Tolerans içinde",IF(B3="600 %10 Gelir ↔ 391 %10",IF(F3>0,"391 %10 fazla: %20 olması gereken matrah %10 gelirde kalmış / çift KDV / mapping hatası olabilir","391 %10 eksik: gelir 391 KDV hesabına eksik aktarılmış olabilir"),IF(B3="600 %20 Gelir ↔ 391 %20",IF(F3>0,"391 %20 fazla: KDV mükerrer veya fazla tahakkuk etmiş olabilir","391 %20 eksik: %20 gelir 391 hesabına eksik aktarılmış olabilir"),IF(B3="610 %10 İade ↔ 191 %10",IF(F3>0,"191 satış iade KDV fazla: iade KDV mükerrer/manuel fazla olabilir","191 satış iade KDV eksik: iade fişi 191 hesabına bağlanmamış olabilir"),IF(B3="610 %20 İade ↔ 191 %20",IF(F3>0,"191 %20 iade KDV fazla olabilir","191 %20 iade KDV eksik olabilir"),IF(B3="602 %20 Ciro/İskonto ↔ 391 İlave",IF(F3>0,"391 ilave KDV fazla: alış iade/ciro primi mapping kontrol","391 ilave KDV eksik: alış iade/ciro primi mapping kontrol"),IF(B3="646 %10 Kur Kârı ↔ 391 İlave",IF(F3>0,"391 ilave KDV fazla: kur farkı KDV oran/hesap eşleşmesi kontrol","391 ilave KDV eksik: kur farkı KDV mapping kontrol"),"Kontrol tanımı dışı")))))))) | I3: KDV1 | J3: 600 %20 gelir ve 391 %20 hesaplanan KDV
A4: =KDV_HESAP_TABANI!A2 | B4: 610 %10 İade ↔ 191 %10 | C4: =KDV_HESAP_TABANI!L2 | D4: =KDV_HESAP_TABANI!M2 | E4: =KDV_HESAP_TABANI!N2 | F4: =KDV_HESAP_TABANI!O2 | G4: =KDV_HESAP_TABANI!P2 | H4: =IF(G4="HAREKET YOK","Hareket yok",IF(G4="TUTUYOR","Tolerans içinde",IF(B4="600 %10 Gelir ↔ 391 %10",IF(F4>0,"391 %10 fazla: %20 olması gereken matrah %10 gelirde kalmış / çift KDV / mapping hatası olabilir","391 %10 eksik: gelir 391 KDV hesabına eksik aktarılmış olabilir"),IF(B4="600 %20 Gelir ↔ 391 %20",IF(F4>0,"391 %20 fazla: KDV mükerrer veya fazla tahakkuk etmiş olabilir","391 %20 eksik: %20 gelir 391 hesabına eksik aktarılmış olabilir"),IF(B4="610 %10 İade ↔ 191 %10",IF(F4>0,"191 satış iade KDV fazla: iade KDV mükerrer/manuel fazla olabilir","191 satış iade KDV eksik: iade fişi 191 hesabına bağlanmamış olabilir"),IF(B4="610 %20 İade ↔ 191 %20",IF(F4>0,"191 %20 iade KDV fazla olabilir","191 %20 iade KDV eksik olabilir"),IF(B4="602 %20 Ciro/İskonto ↔ 391 İlave",IF(F4>0,"391 ilave KDV fazla: alış iade/ciro primi mapping kontrol","391 ilave KDV eksik: alış iade/ciro primi mapping kontrol"),IF(B4="646 %10 Kur Kârı ↔ 391 İlave",IF(F4>0,"391 ilave KDV fazla: kur farkı KDV oran/hesap eşleşmesi kontrol","391 ilave KDV eksik: kur farkı KDV mapping kontrol"),"Kontrol tanımı dışı")))))))) | I4: KDV1 | J4: 610 satış iadesi fişi ve 191 satıştan iade KDV
A5: =KDV_HESAP_TABANI!A2 | B5: 610 %20 İade ↔ 191 %20 | C5: =KDV_HESAP_TABANI!Q2 | D5: =KDV_HESAP_TABANI!R2 | E5: =KDV_HESAP_TABANI!S2 | F5: =KDV_HESAP_TABANI!T2 | G5: =KDV_HESAP_TABANI!U2 | H5: =IF(G5="HAREKET YOK","Hareket yok",IF(G5="TUTUYOR","Tolerans içinde",IF(B5="600 %10 Gelir ↔ 391 %10",IF(F5>0,"391 %10 fazla: %20 olması gereken matrah %10 gelirde kalmış / çift KDV / mapping hatası olabilir","391 %10 eksik: gelir 391 KDV hesabına eksik aktarılmış olabilir"),IF(B5="600 %20 Gelir ↔ 391 %20",IF(F5>0,"391 %20 fazla: KDV mükerrer veya fazla tahakkuk etmiş olabilir","391 %20 eksik: %20 gelir 391 hesabına eksik aktarılmış olabilir"),IF(B5="610 %10 İade ↔ 191 %10",IF(F5>0,"191 satış iade KDV fazla: iade KDV mükerrer/manuel fazla olabilir","191 satış iade KDV eksik: iade fişi 191 hesabına bağlanmamış olabilir"),IF(B5="610 %20 İade ↔ 191 %20",IF(F5>0,"191 %20 iade KDV fazla olabilir","191 %20 iade KDV eksik olabilir"),IF(B5="602 %20 Ciro/İskonto ↔ 391 İlave",IF(F5>0,"391 ilave KDV fazla: alış iade/ciro primi mapping kontrol","391 ilave KDV eksik: alış iade/ciro primi mapping kontrol"),IF(B5="646 %10 Kur Kârı ↔ 391 İlave",IF(F5>0,"391 ilave KDV fazla: kur farkı KDV oran/hesap eşleşmesi kontrol","391 ilave KDV eksik: kur farkı KDV mapping kontrol"),"Kontrol tanımı dışı")))))))) | I5: KDV1 | J5: 610 %20 satış iadesi fişi ve 191 %20 iade KDV
A6: =KDV_HESAP_TABANI!A2 | B6: 602 %20 Ciro/İskonto ↔ 391 İlave | C6: =KDV_HESAP_TABANI!V2 | D6: =KDV_HESAP_TABANI!W2 | E6: =KDV_HESAP_TABANI!X2 | F6: =KDV_HESAP_TABANI!Y2 | G6: =KDV_HESAP_TABANI!Z2 | H6: =IF(G6="HAREKET YOK","Hareket yok",IF(G6="TUTUYOR","Tolerans içinde",IF(B6="600 %10 Gelir ↔ 391 %10",IF(F6>0,"391 %10 fazla: %20 olması gereken matrah %10 gelirde kalmış / çift KDV / mapping hatası olabilir","391 %10 eksik: gelir 391 KDV hesabına eksik aktarılmış olabilir"),IF(B6="600 %20 Gelir ↔ 391 %20",IF(F6>0,"391 %20 fazla: KDV mükerrer veya fazla tahakkuk etmiş olabilir","391 %20 eksik: %20 gelir 391 hesabına eksik aktarılmış olabilir"),IF(B6="610 %10 İade ↔ 191 %10",IF(F6>0,"191 satış iade KDV fazla: iade KDV mükerrer/manuel fazla olabilir","191 satış iade KDV eksik: iade fişi 191 hesabına bağlanmamış olabilir"),IF(B6="610 %20 İade ↔ 191 %20",IF(F6>0,"191 %20 iade KDV fazla olabilir","191 %20 iade KDV eksik olabilir"),IF(B6="602 %20 Ciro/İskonto ↔ 391 İlave",IF(F6>0,"391 ilave KDV fazla: alış iade/ciro primi mapping kontrol","391 ilave KDV eksik: alış iade/ciro primi mapping kontrol"),IF(B6="646 %10 Kur Kârı ↔ 391 İlave",IF(F6>0,"391 ilave KDV fazla: kur farkı KDV oran/hesap eşleşmesi kontrol","391 ilave KDV eksik: kur farkı KDV mapping kontrol"),"Kontrol tanımı dışı")))))))) | I6: KDV1 | J6: 602 ciro/iskonto geliri ve 391 ilave KDV
A7: =KDV_HESAP_TABANI!A2 | B7: 646 %10 Kur Kârı ↔ 391 İlave | C7: =KDV_HESAP_TABANI!AA2 | D7: =KDV_HESAP_TABANI!AB2 | E7: =KDV_HESAP_TABANI!AC2 | F7: =KDV_HESAP_TABANI!AD2 | G7: =KDV_HESAP_TABANI!AE2 | H7: =IF(G7="HAREKET YOK","Hareket yok",IF(G7="TUTUYOR","Tolerans içinde",IF(B7="600 %10 Gelir ↔ 391 %10",IF(F7>0,"391 %10 fazla: %20 olması gereken matrah %10 gelirde kalmış / çift KDV / mapping hatası olabilir","391 %10 eksik: gelir 391 KDV hesabına eksik aktarılmış olabilir"),IF(B7="600 %20 Gelir ↔ 391 %20",IF(F7>0,"391 %20 fazla: KDV mükerrer veya fazla tahakkuk etmiş olabilir","391 %20 eksik: %20 gelir 391 hesabına eksik aktarılmış olabilir"),IF(B7="610 %10 İade ↔ 191 %10",IF(F7>0,"191 satış iade KDV fazla: iade KDV mükerrer/manuel fazla olabilir","191 satış iade KDV eksik: iade fişi 191 hesabına bağlanmamış olabilir"),IF(B7="610 %20 İade ↔ 191 %20",IF(F7>0,"191 %20 iade KDV fazla olabilir","191 %20 iade KDV eksik olabilir"),IF(B7="602 %20 Ciro/İskonto ↔ 391 İlave",IF(F7>0,"391 ilave KDV fazla: alış iade/ciro primi mapping kontrol","391 ilave KDV eksik: alış iade/ciro primi mapping kontrol"),IF(B7="646 %10 Kur Kârı ↔ 391 İlave",IF(F7>0,"391 ilave KDV fazla: kur farkı KDV oran/hesap eşleşmesi kontrol","391 ilave KDV eksik: kur farkı KDV mapping kontrol"),"Kontrol tanımı dışı")))))))) | I7: KDV1 | J7: 646 kur farkı ve 391 ilave KDV
A8: =KDV_HESAP_TABANI!A3 | B8: 600 %10 Gelir ↔ 391 %10 | C8: =KDV_HESAP_TABANI!B3 | D8: =KDV_HESAP_TABANI!C3 | E8: =KDV_HESAP_TABANI!D3 | F8: =KDV_HESAP_TABANI!E3 | G8: =KDV_HESAP_TABANI!F3 | H8: =IF(G8="HAREKET YOK","Hareket yok",IF(G8="TUTUYOR","Tolerans içinde",IF(B8="600 %10 Gelir ↔ 391 %10",IF(F8>0,"391 %10 fazla: %20 olması gereken matrah %10 gelirde kalmış / çift KDV / mapping hatası olabilir","391 %10 eksik: gelir 391 KDV hesabına eksik aktarılmış olabilir"),IF(B8="600 %20 Gelir ↔ 391 %20",IF(F8>0,"391 %20 fazla: KDV mükerrer veya fazla tahakkuk etmiş olabilir","391 %20 eksik: %20 gelir 391 hesabına eksik aktarılmış olabilir"),IF(B8="610 %10 İade ↔ 191 %10",IF(F8>0,"191 satış iade KDV fazla: iade KDV mükerrer/manuel fazla olabilir","191 satış iade KDV eksik: iade fişi 191 hesabına bağlanmamış olabilir"),IF(B8="610 %20 İade ↔ 191 %20",IF(F8>0,"191 %20 iade KDV fazla olabilir","191 %20 iade KDV eksik olabilir"),IF(B8="602 %20 Ciro/İskonto ↔ 391 İlave",IF(F8>0,"391 ilave KDV fazla: alış iade/ciro primi mapping kontrol","391 ilave KDV eksik: alış iade/ciro primi mapping kontrol"),IF(B8="646 %10 Kur Kârı ↔ 391 İlave",IF(F8>0,"391 ilave KDV fazla: kur farkı KDV oran/hesap eşleşmesi kontrol","391 ilave KDV eksik: kur farkı KDV mapping kontrol"),"Kontrol tanımı dışı")))))))) | I8: KDV1 | J8: 600/391 gelir entegrasyon fişi ve ürün-KDV oran mapping
A9: =KDV_HESAP_TABANI!A3 | B9: 600 %20 Gelir ↔ 391 %20 | C9: =KDV_HESAP_TABANI!G3 | D9: =KDV_HESAP_TABANI!H3 | E9: =KDV_HESAP_TABANI!I3 | F9: =KDV_HESAP_TABANI!J3 | G9: =KDV_HESAP_TABANI!K3 | H9: =IF(G9="HAREKET YOK","Hareket yok",IF(G9="TUTUYOR","Tolerans içinde",IF(B9="600 %10 Gelir ↔ 391 %10",IF(F9>0,"391 %10 fazla: %20 olması gereken matrah %10 gelirde kalmış / çift KDV / mapping hatası olabilir","391 %10 eksik: gelir 391 KDV hesabına eksik aktarılmış olabilir"),IF(B9="600 %20 Gelir ↔ 391 %20",IF(F9>0,"391 %20 fazla: KDV mükerrer veya fazla tahakkuk etmiş olabilir","391 %20 eksik: %20 gelir 391 hesabına eksik aktarılmış olabilir"),IF(B9="610 %10 İade ↔ 191 %10",IF(F9>0,"191 satış iade KDV fazla: iade KDV mükerrer/manuel fazla olabilir","191 satış iade KDV eksik: iade fişi 191 hesabına bağlanmamış olabilir"),IF(B9="610 %20 İade ↔ 191 %20",IF(F9>0,"191 %20 iade KDV fazla olabilir","191 %20 iade KDV eksik olabilir"),IF(B9="602 %20 Ciro/İskonto ↔ 391 İlave",IF(F9>0,"391 ilave KDV fazla: alış iade/ciro primi mapping kontrol","391 ilave KDV eksik: alış iade/ciro primi mapping kontrol"),IF(B9="646 %10 Kur Kârı ↔ 391 İlave",IF(F9>0,"391 ilave KDV fazla: kur farkı KDV oran/hesap eşleşmesi kontrol","391 ilave KDV eksik: kur farkı KDV mapping kontrol"),"Kontrol tanımı dışı")))))))) | I9: KDV1 | J9: 600 %20 gelir ve 391 %20 hesaplanan KDV
A10: =KDV_HESAP_TABANI!A3 | B10: 610 %10 İade ↔ 191 %10 | C10: =KDV_HESAP_TABANI!L3 | D10: =KDV_HESAP_TABANI!M3 | E10: =KDV_HESAP_TABANI!N3 | F10: =KDV_HESAP_TABANI!O3 | G10: =KDV_HESAP_TABANI!P3 | H10: =IF(G10="HAREKET YOK","Hareket yok",IF(G10="TUTUYOR","Tolerans içinde",IF(B10="600 %10 Gelir ↔ 391 %10",IF(F10>0,"391 %10 fazla: %20 olması gereken matrah %10 gelirde kalmış / çift KDV / mapping hatası olabilir","391 %10 eksik: gelir 391 KDV hesabına eksik aktarılmış olabilir"),IF(B10="600 %20 Gelir ↔ 391 %20",IF(F10>0,"391 %20 fazla: KDV mükerrer veya fazla tahakkuk etmiş olabilir","391 %20 eksik: %20 gelir 391 hesabına eksik aktarılmış olabilir"),IF(B10="610 %10 İade ↔ 191 %10",IF(F10>0,"191 satış iade KDV fazla: iade KDV mükerrer/manuel fazla olabilir","191 satış iade KDV eksik: iade fişi 191 hesabına bağlanmamış olabilir"),IF(B10="610 %20 İade ↔ 191 %20",IF(F10>0,"191 %20 iade KDV fazla olabilir","191 %20 iade KDV eksik olabilir"),IF(B10="602 %20 Ciro/İskonto ↔ 391 İlave",IF(F10>0,"391 ilave KDV fazla: alış iade/ciro primi mapping kontrol","391 ilave KDV eksik: alış iade/ciro primi mapping kontrol"),IF(B10="646 %10 Kur Kârı ↔ 391 İlave",IF(F10>0,"391 ilave KDV fazla: kur farkı KDV oran/hesap eşleşmesi kontrol","391 ilave KDV eksik: kur farkı KDV mapping kontrol"),"Kontrol tanımı dışı")))))))) | I10: KDV1 | J10: 610 satış iadesi fişi ve 191 satıştan iade KDV
A11: =KDV_HESAP_TABANI!A3 | B11: 610 %20 İade ↔ 191 %20 | C11: =KDV_HESAP_TABANI!Q3 | D11: =KDV_HESAP_TABANI!R3 | E11: =KDV_HESAP_TABANI!S3 | F11: =KDV_HESAP_TABANI!T3 | G11: =KDV_HESAP_TABANI!U3 | H11: =IF(G11="HAREKET YOK","Hareket yok",IF(G11="TUTUYOR","Tolerans içinde",IF(B11="600 %10 Gelir ↔ 391 %10",IF(F11>0,"391 %10 fazla: %20 olması gereken matrah %10 gelirde kalmış / çift KDV / mapping hatası olabilir","391 %10 eksik: gelir 391 KDV hesabına eksik aktarılmış olabilir"),IF(B11="600 %20 Gelir ↔ 391 %20",IF(F11>0,"391 %20 fazla: KDV mükerrer veya fazla tahakkuk etmiş olabilir","391 %20 eksik: %20 gelir 391 hesabına eksik aktarılmış olabilir"),IF(B11="610 %10 İade ↔ 191 %10",IF(F11>0,"191 satış iade KDV fazla: iade KDV mükerrer/manuel fazla olabilir","191 satış iade KDV eksik: iade fişi 191 hesabına bağlanmamış olabilir"),IF(B11="610 %20 İade ↔ 191 %20",IF(F11>0,"191 %20 iade KDV fazla olabilir","191 %20 iade KDV eksik olabilir"),IF(B11="602 %20 Ciro/İskonto ↔ 391 İlave",IF(F11>0,"391 ilave KDV fazla: alış iade/ciro primi mapping kontrol","391 ilave KDV eksik: alış iade/ciro primi mapping kontrol"),IF(B11="646 %10 Kur Kârı ↔ 391 İlave",IF(F11>0,"391 ilave KDV fazla: kur farkı KDV oran/hesap eşleşmesi kontrol","391 ilave KDV eksik: kur farkı KDV mapping kontrol"),"Kontrol tanımı dışı")))))))) | I11: KDV1 | J11: 610 %20 satış iadesi fişi ve 191 %20 iade KDV
A12: =KDV_HESAP_TABANI!A3 | B12: 602 %20 Ciro/İskonto ↔ 391 İlave | C12: =KDV_HESAP_TABANI!V3 | D12: =KDV_HESAP_TABANI!W3 | E12: =KDV_HESAP_TABANI!X3 | F12: =KDV_HESAP_TABANI!Y3 | G12: =KDV_HESAP_TABANI!Z3 | H12: =IF(G12="HAREKET YOK","Hareket yok",IF(G12="TUTUYOR","Tolerans içinde",IF(B12="600 %10 Gelir ↔ 391 %10",IF(F12>0,"391 %10 fazla: %20 olması gereken matrah %10 gelirde kalmış / çift KDV / mapping hatası olabilir","391 %10 eksik: gelir 391 KDV hesabına eksik aktarılmış olabilir"),IF(B12="600 %20 Gelir ↔ 391 %20",IF(F12>0,"391 %20 fazla: KDV mükerrer veya fazla tahakkuk etmiş olabilir","391 %20 eksik: %20 gelir 391 hesabına eksik aktarılmış olabilir"),IF(B12="610 %10 İade ↔ 191 %10",IF(F12>0,"191 satış iade KDV fazla: iade KDV mükerrer/manuel fazla olabilir","191 satış iade KDV eksik: iade fişi 191 hesabına bağlanmamış olabilir"),IF(B12="610 %20 İade ↔ 191 %20",IF(F12>0,"191 %20 iade KDV fazla olabilir","191 %20 iade KDV eksik olabilir"),IF(B12="602 %20 Ciro/İskonto ↔ 391 İlave",IF(F12>0,"391 ilave KDV fazla: alış iade/ciro primi mapping kontrol","391 ilave KDV eksik: alış iade/ciro primi mapping kontrol"),IF(B12="646 %10 Kur Kârı ↔ 391 İlave",IF(F12>0,"391 ilave KDV fazla: kur farkı KDV oran/hesap eşleşmesi kontrol","391 ilave KDV eksik: kur farkı KDV mapping kontrol"),"Kontrol tanımı dışı")))))))) | I12: KDV1 | J12: 602 ciro/iskonto geliri ve 391 ilave KDV
A13: =KDV_HESAP_TABANI!A3 | B13: 646 %10 Kur Kârı ↔ 391 İlave | C13: =KDV_HESAP_TABANI!AA3 | D13: =KDV_HESAP_TABANI!AB3 | E13: =KDV_HESAP_TABANI!AC3 | F13: =KDV_HESAP_TABANI!AD3 | G13: =KDV_HESAP_TABANI!AE3 | H13: =IF(G13="HAREKET YOK","Hareket yok",IF(G13="TUTUYOR","Tolerans içinde",IF(B13="600 %10 Gelir ↔ 391 %10",IF(F13>0,"391 %10 fazla: %20 olması gereken matrah %10 gelirde kalmış / çift KDV / mapping hatası olabilir","391 %10 eksik: gelir 391 KDV hesabına eksik aktarılmış olabilir"),IF(B13="600 %20 Gelir ↔ 391 %20",IF(F13>0,"391 %20 fazla: KDV mükerrer veya fazla tahakkuk etmiş olabilir","391 %20 eksik: %20 gelir 391 hesabına eksik aktarılmış olabilir"),IF(B13="610 %10 İade ↔ 191 %10",IF(F13>0,"191 satış iade KDV fazla: iade KDV mükerrer/manuel fazla olabilir","191 satış iade KDV eksik: iade fişi 191 hesabına bağlanmamış olabilir"),IF(B13="610 %20 İade ↔ 191 %20",IF(F13>0,"191 %20 iade KDV fazla olabilir","191 %20 iade KDV eksik olabilir"),IF(B13="602 %20 Ciro/İskonto ↔ 391 İlave",IF(F13>0,"391 ilave KDV fazla: alış iade/ciro primi mapping kontrol","391 ilave KDV eksik: alış iade/ciro primi mapping kontrol"),IF(B13="646 %10 Kur Kârı ↔ 391 İlave",IF(F13>0,"391 ilave KDV fazla: kur farkı KDV oran/hesap eşleşmesi kontrol","391 ilave KDV eksik: kur farkı KDV mapping kontrol"),"Kontrol tanımı dışı")))))))) | I13: KDV1 | J13: 646 kur farkı ve 391 ilave KDV
A14: =KDV_HESAP_TABANI!A4 | B14: 600 %10 Gelir ↔ 391 %10 | C14: =KDV_HESAP_TABANI!B4 | D14: =KDV_HESAP_TABANI!C4 | E14: =KDV_HESAP_TABANI!D4 | F14: =KDV_HESAP_TABANI!E4 | G14: =KDV_HESAP_TABANI!F4 | H14: =IF(G14="HAREKET YOK","Hareket yok",IF(G14="TUTUYOR","Tolerans içinde",IF(B14="600 %10 Gelir ↔ 391 %10",IF(F14>0,"391 %10 fazla: %20 olması gereken matrah %10 gelirde kalmış / çift KDV / mapping hatası olabilir","391 %10 eksik: gelir 391 KDV hesabına eksik aktarılmış olabilir"),IF(B14="600 %20 Gelir ↔ 391 %20",IF(F14>0,"391 %20 fazla: KDV mükerrer veya fazla tahakkuk etmiş olabilir","391 %20 eksik: %20 gelir 391 hesabına eksik aktarılmış olabilir"),IF(B14="610 %10 İade ↔ 191 %10",IF(F14>0,"191 satış iade KDV fazla: iade KDV mükerrer/manuel fazla olabilir","191 satış iade KDV eksik: iade fişi 191 hesabına bağlanmamış olabilir"),IF(B14="610 %20 İade ↔ 191 %20",IF(F14>0,"191 %20 iade KDV fazla olabilir","191 %20 iade KDV eksik olabilir"),IF(B14="602 %20 Ciro/İskonto ↔ 391 İlave",IF(F14>0,"391 ilave KDV fazla: alış iade/ciro primi mapping kontrol","391 ilave KDV eksik: alış iade/ciro primi mapping kontrol"),IF(B14="646 %10 Kur Kârı ↔ 391 İlave",IF(F14>0,"391 ilave KDV fazla: kur farkı KDV oran/hesap eşleşmesi kontrol","391 ilave KDV eksik: kur farkı KDV mapping kontrol"),"Kontrol tanımı dışı")))))))) | I14: KDV1 | J14: 600/391 gelir entegrasyon fişi ve ürün-KDV oran mapping
A15: =KDV_HESAP_TABANI!A4 | B15: 600 %20 Gelir ↔ 391 %20 | C15: =KDV_HESAP_TABANI!G4 | D15: =KDV_HESAP_TABANI!H4 | E15: =KDV_HESAP_TABANI!I4 | F15: =KDV_HESAP_TABANI!J4 | G15: =KDV_HESAP_TABANI!K4 | H15: =IF(G15="HAREKET YOK","Hareket yok",IF(G15="TUTUYOR","Tolerans içinde",IF(B15="600 %10 Gelir ↔ 391 %10",IF(F15>0,"391 %10 fazla: %20 olması gereken matrah %10 gelirde kalmış / çift KDV / mapping hatası olabilir","391 %10 eksik: gelir 391 KDV hesabına eksik aktarılmış olabilir"),IF(B15="600 %20 Gelir ↔ 391 %20",IF(F15>0,"391 %20 fazla: KDV mükerrer veya fazla tahakkuk etmiş olabilir","391 %20 eksik: %20 gelir 391 hesabına eksik aktarılmış olabilir"),IF(B15="610 %10 İade ↔ 191 %10",IF(F15>0,"191 satış iade KDV fazla: iade KDV mükerrer/manuel fazla olabilir","191 satış iade KDV eksik: iade fişi 191 hesabına bağlanmamış olabilir"),IF(B15="610 %20 İade ↔ 191 %20",IF(F15>0,"191 %20 iade KDV fazla olabilir","191 %20 iade KDV eksik olabilir"),IF(B15="602 %20 Ciro/İskonto ↔ 391 İlave",IF(F15>0,"391 ilave KDV fazla: alış iade/ciro primi mapping kontrol","391 ilave KDV eksik: alış iade/ciro primi mapping kontrol"),IF(B15="646 %10 Kur Kârı ↔ 391 İlave",IF(F15>0,"391 ilave KDV fazla: kur farkı KDV oran/hesap eşleşmesi kontrol","391 ilave KDV eksik: kur farkı KDV mapping kontrol"),"Kontrol tanımı dışı")))))))) | I15: KDV1 | J15: 600 %20 gelir ve 391 %20 hesaplanan KDV
A16: =KDV_HESAP_TABANI!A4 | B16: 610 %10 İade ↔ 191 %10 | C16: =KDV_HESAP_TABANI!L4 | D16: =KDV_HESAP_TABANI!M4 | E16: =KDV_HESAP_TABANI!N4 | F16: =KDV_HESAP_TABANI!O4 | G16: =KDV_HESAP_TABANI!P4 | H16: =IF(G16="HAREKET YOK","Hareket yok",IF(G16="TUTUYOR","Tolerans içinde",IF(B16="600 %10 Gelir ↔ 391 %10",IF(F16>0,"391 %10 fazla: %20 olması gereken matrah %10 gelirde kalmış / çift KDV / mapping hatası olabilir","391 %10 eksik: gelir 391 KDV hesabına eksik aktarılmış olabilir"),IF(B16="600 %20 Gelir ↔ 391 %20",IF(F16>0,"391 %20 fazla: KDV mükerrer veya fazla tahakkuk etmiş olabilir","391 %20 eksik: %20 gelir 391 hesabına eksik aktarılmış olabilir"),IF(B16="610 %10 İade ↔ 191 %10",IF(F16>0,"191 satış iade KDV fazla: iade KDV mükerrer/manuel fazla olabilir","191 satış iade KDV eksik: iade fişi 191 hesabına bağlanmamış olabilir"),IF(B16="610 %20 İade ↔ 191 %20",IF(F16>0,"191 %20 iade KDV fazla olabilir","191 %20 iade KDV eksik olabilir"),IF(B16="602 %20 Ciro/İskonto ↔ 391 İlave",IF(F16>0,"391 ilave KDV fazla: alış iade/ciro primi mapping kontrol","391 ilave KDV eksik: alış iade/ciro primi mapping kontrol"),IF(B16="646 %10 Kur Kârı ↔ 391 İlave",IF(F16>0,"391 ilave KDV fazla: kur farkı KDV oran/hesap eşleşmesi kontrol","391 ilave KDV eksik: kur farkı KDV mapping kontrol"),"Kontrol tanımı dışı")))))))) | I16: KDV1 | J16: 610 satış iadesi fişi ve 191 satıştan iade KDV
A17: =KDV_HESAP_TABANI!A4 | B17: 610 %20 İade ↔ 191 %20 | C17: =KDV_HESAP_TABANI!Q4 | D17: =KDV_HESAP_TABANI!R4 | E17: =KDV_HESAP_TABANI!S4 | F17: =KDV_HESAP_TABANI!T4 | G17: =KDV_HESAP_TABANI!U4 | H17: =IF(G17="HAREKET YOK","Hareket yok",IF(G17="TUTUYOR","Tolerans içinde",IF(B17="600 %10 Gelir ↔ 391 %10",IF(F17>0,"391 %10 fazla: %20 olması gereken matrah %10 gelirde kalmış / çift KDV / mapping hatası olabilir","391 %10 eksik: gelir 391 KDV hesabına eksik aktarılmış olabilir"),IF(B17="600 %20 Gelir ↔ 391 %20",IF(F17>0,"391 %20 fazla: KDV mükerrer veya fazla tahakkuk etmiş olabilir","391 %20 eksik: %20 gelir 391 hesabına eksik aktarılmış olabilir"),IF(B17="610 %10 İade ↔ 191 %10",IF(F17>0,"191 satış iade KDV fazla: iade KDV mükerrer/manuel fazla olabilir","191 satış iade KDV eksik: iade fişi 191 hesabına bağlanmamış olabilir"),IF(B17="610 %20 İade ↔ 191 %20",IF(F17>0,"191 %20 iade KDV fazla olabilir","191 %20 iade KDV eksik olabilir"),IF(B17="602 %20 Ciro/İskonto ↔ 391 İlave",IF(F17>0,"391 ilave KDV fazla: alış iade/ciro primi mapping kontrol","391 ilave KDV eksik: alış iade/ciro primi mapping kontrol"),IF(B17="646 %10 Kur Kârı ↔ 391 İlave",IF(F17>0,"391 ilave KDV fazla: kur farkı KDV oran/hesap eşleşmesi kontrol","391 ilave KDV eksik: kur farkı KDV mapping kontrol"),"Kontrol tanımı dışı")))))))) | I17: KDV1 | J17: 610 %20 satış iadesi fişi ve 191 %20 iade KDV
A18: =KDV_HESAP_TABANI!A4 | B18: 602 %20 Ciro/İskonto ↔ 391 İlave | C18: =KDV_HESAP_TABANI!V4 | D18: =KDV_HESAP_TABANI!W4 | E18: =KDV_HESAP_TABANI!X4 | F18: =KDV_HESAP_TABANI!Y4 | G18: =KDV_HESAP_TABANI!Z4 | H18: =IF(G18="HAREKET YOK","Hareket yok",IF(G18="TUTUYOR","Tolerans içinde",IF(B18="600 %10 Gelir ↔ 391 %10",IF(F18>0,"391 %10 fazla: %20 olması gereken matrah %10 gelirde kalmış / çift KDV / mapping hatası olabilir","391 %10 eksik: gelir 391 KDV hesabına eksik aktarılmış olabilir"),IF(B18="600 %20 Gelir ↔ 391 %20",IF(F18>0,"391 %20 fazla: KDV mükerrer veya fazla tahakkuk etmiş olabilir","391 %20 eksik: %20 gelir 391 hesabına eksik aktarılmış olabilir"),IF(B18="610 %10 İade ↔ 191 %10",IF(F18>0,"191 satış iade KDV fazla: iade KDV mükerrer/manuel fazla olabilir","191 satış iade KDV eksik: iade fişi 191 hesabına bağlanmamış olabilir"),IF(B18="610 %20 İade ↔ 191 %20",IF(F18>0,"191 %20 iade KDV fazla olabilir","191 %20 iade KDV eksik olabilir"),IF(B18="602 %20 Ciro/İskonto ↔ 391 İlave",IF(F18>0,"391 ilave KDV fazla: alış iade/ciro primi mapping kontrol","391 ilave KDV eksik: alış iade/ciro primi mapping kontrol"),IF(B18="646 %10 Kur Kârı ↔ 391 İlave",IF(F18>0,"391 ilave KDV fazla: kur farkı KDV oran/hesap eşleşmesi kontrol","391 ilave KDV eksik: kur farkı KDV mapping kontrol"),"Kontrol tanımı dışı")))))))) | I18: KDV1 | J18: 602 ciro/iskonto geliri ve 391 ilave KDV
A19: =KDV_HESAP_TABANI!A4 | B19: 646 %10 Kur Kârı ↔ 391 İlave | C19: =KDV_HESAP_TABANI!AA4 | D19: =KDV_HESAP_TABANI!AB4 | E19: =KDV_HESAP_TABANI!AC4 | F19: =KDV_HESAP_TABANI!AD4 | G19: =KDV_HESAP_TABANI!AE4 | H19: =IF(G19="HAREKET YOK","Hareket yok",IF(G19="TUTUYOR","Tolerans içinde",IF(B19="600 %10 Gelir ↔ 391 %10",IF(F19>0,"391 %10 fazla: %20 olması gereken matrah %10 gelirde kalmış / çift KDV / mapping hatası olabilir","391 %10 eksik: gelir 391 KDV hesabına eksik aktarılmış olabilir"),IF(B19="600 %20 Gelir ↔ 391 %20",IF(F19>0,"391 %20 fazla: KDV mükerrer veya fazla tahakkuk etmiş olabilir","391 %20 eksik: %20 gelir 391 hesabına eksik aktarılmış olabilir"),IF(B19="610 %10 İade ↔ 191 %10",IF(F19>0,"191 satış iade KDV fazla: iade KDV mükerrer/manuel fazla olabilir","191 satış iade KDV eksik: iade fişi 191 hesabına bağlanmamış olabilir"),IF(B19="610 %20 İade ↔ 191 %20",IF(F19>0,"191 %20 iade KDV fazla olabilir","191 %20 iade KDV eksik olabilir"),IF(B19="602 %20 Ciro/İskonto ↔ 391 İlave",IF(F19>0,"391 ilave KDV fazla: alış iade/ciro primi mapping kontrol","391 ilave KDV eksik: alış iade/ciro primi mapping kontrol"),IF(B19="646 %10 Kur Kârı ↔ 391 İlave",IF(F19>0,"391 ilave KDV fazla: kur farkı KDV oran/hesap eşleşmesi kontrol","391 ilave KDV eksik: kur farkı KDV mapping kontrol"),"Kontrol tanımı dışı")))))))) | I19: KDV1 | J19: 646 kur farkı ve 391 ilave KDV
